Workbook

Sheet Sheet1
A1: Account: Account Name | B1: Account: DBA 1 | C1: Account: DBA 2 | D1: Account: DBA 3 | E1: Account: Shipping Street 1 | F1: Account: Shipping Street 2 | G1: Account: Shipping City | H1: Account:ShippingState/Province | I1: Account: Shipping Zip/Postal Code | J1: Account: Shipping Country | K1: Account: Phone | L1: Account: Website | M1: Account:AirportCode | N1: Bus Category 1 | O1: Bus Category 2 | P1: Bus Category 3 | Q1: Bus Category 4 | R1: Bus Category 5 | S1: SyncStatus | T1: Google:SyncByPhone | U1: Google:SyncByNameAndAddress | V1: Google:SyncByWebsite | W1: Google:SyncByName | X1: Google:SyncByNearby | Y1: Google:MapsURL | Z1: Google:JSONCandidate | AA1: Google:JSONNearby | AB1: Google:CompanyName | AC1: Google:BusinessStatus | AD1: Google:PlaceID | AE1: Google:FormattedAddress | AF1: MatchStreet | AG1: MatchCity | AH1: MatchState | AI1: MatchZip | AJ1: Google:Latitude | AK1: Google:Longitude | AL1: Google:PlacesDetailsJSON | AM1: Google:AdrAddress | AN1: Google:FormattedPhone | AO1: Google:Icon | AP1: Google:ID | AQ1: Google:InternationalPhone | AR1: Google:ListingTypes | AS1: Google:UTCOffset | AT1: Google:Vicinity | AU1: Google:BusinessURL | AV1: Google:Rating | AW1: Google:NumReviews | AX1: Google:PriceLevel | AY1: Google:GlobalCode | AZ1: Google:CompoundCode | BA1: Google:OpeningHours
A2: 1 Vision Aviation | E2: 2044 Scanlan Ave | G2: Salina | H2: KS | I2: 67401 | J2: US | L2: http://1vision.aero/ | M2: SLN | N2: P145 | O2: REPO | P2: HANG | Y2: https://maps.google.com/?cid=14747138387774421522 | AB2: 1 Vision Aviation | AC2: OPERATIONAL | AD2: ChIJp2g5XB7JvIcREjrS4DpcqMw | AE2: 2044 Scanlan Ave, Salina, KS 67401, USA | AJ2: 38.807358 | AK2: -97.637337 | AL2: {"html_attributions":[],"result":{"address_components":[{"long_name":"2044","short_name":"2044","types":["street_number"]},{"long_name":"Scanlan Avenue","short_name":"Scanlan Ave","types":["route"]},{"long_name":"Salina","short_name":"Salina","types":["locality","political"]},{"long_name":"Saline County","short_name":"Saline County","types":["administrative_area_level_2","political"]},{"long_name":"Kansas","short_name":"KS","types":["administrative_area_level_1","political"]},{"long_name":"United States","short_name":"US","types":["country","political"]},{"long_name":"67401","short_name":"67401","types":["postal_code"]}],"adr_address":"<span class=\"street-address\">2044 Scanlan Ave</span>, <span class=\"locality\">Salina</span>, <span class=\"region\">KS</span> <span class=\"postal-code\">67401</span>, <span class=\"country-name\">USA</span>","formatted_address":"2044 Scanlan Ave, Salina, KS 67401, USA","formatted_phone_number":null,"geometry":{"location":{"lat":38.80735769999999,"lng":-97.63733669999999},"viewport":{"northeast":{"lat":38.80870703029149,"lng":-97.6355214197085},"southwest":{"lat":38.80600906970849,"lng":-97.6382193802915}}},"icon":"https://maps.gstatic.com/mapfiles/place_api/icons/v1/png_71/generic_business-71.png","id":null,"international_phone_number":null,"name":"1 Vision Aviation","place_id":"ChIJp2g5XB7JvIcREjrS4DpcqMw","rating":3.7,"reference":null,"reviews":[{"author_name":"Bobby Whiteman","author_url":"https://www.google.com/maps/contrib/109708439715971637247/reviews","language":"en","profile_photo_url":"https://lh3.googleusercontent.com/a/AATXAJwOg45O_L9TKpjKclElZALwu1ES7B5HWNRNP8iu=s128-c0x00000000-cc-rp-mo","rating":1,"relative_time_description":"10 months ago","text":"Had to give a full star because it wont let you give half star rating.surprised this place is still in buisiness.","time":1614626368},{"author_name":"Ethan Bertrand","author_url":"https://www.google.com/maps/contrib/108556567451515714129/reviews","language":"en","profile_photo_url":"https://lh3.googleusercontent.com/a/AATXAJxU38FBP5oPKcf_BjJEYKYVCDcDY7cc0JSJFlWl=s128-c0x00000000-cc-rp-mo","rating":5,"relative_time_description":"11 months ago","text":"Jimmy and team are knowledgeable, respectful and easy to work with.","time":1611253702},{"author_name":"Jett Vann","author_url":"https://www.google.com/maps/contrib/114548707315401440630/reviews","language":null,"profile_photo_url":"https://lh3.googleusercontent.com/a-/AOh14GjSQ5dAamUoCUqA0833Gp1LKWcAevssjZCjJ3i8=s128-c0x00000000-cc-rp-mo","rating":5,"relative_time_description":"9 months ago","text":"","time":1616819256},{"author_name":"Biruk Alemu","author_url":"https://www.google.com/maps/contrib/111253678928477014522/reviews","language":null,"profile_photo_url":"https://lh3.googleusercontent.com/a/AATXAJx4MNEjS5UkaOFCeLEDf7y_toRAG7u1MuE_c6sy=s128-c0x00000000-cc-rp-mo","rating":5,"relative_time_description":"a year ago","text":"","time":1606802599},{"author_name":"Amanda Monthei","author_url":"https://www.google.com/maps/contrib/116577537071926482113/reviews","language":null,"profile_photo_url":"https://lh3.googleusercontent.com/a/AATXAJwyVQTN6YVPIG--AFSsx1DHORRc8eTmffjc0lDq=s128-c0x00000000-cc-rp-mo","rating":1,"relative_time_description":"5 months ago","text":"","time":1626375660}],"types":["point_of_interest","establishment"],"url":"https://maps.google.com/?cid=14747138387774421522","utc_offset":-360,"vicinity":"2044 Scanlan Avenue, Salina","website":"http://1vision.aero/"},"status":"OK"} | AM2: <span class="street-address">2044 Scanlan Ave</span>, <span class="locality">Salina</span>, <span class="region">KS</span> <span class="postal-code">67401</span>, <span class="country-name">USA</span> | AO2: https://maps.gstatic.com/mapfiles/place_api/icons/v1/png_71/generic_business-71.png | AR2: point_of_interest,establishment | AS2: -360 | AT2: 2044 Scanlan Avenue, Salina | AU2: http://1vision.aero/ | AV2: 3.7 | AW2: 5
A3: 24/7 Flight Support | E3: 14121 NE Airport Way | G3: Portland | H3: OR | I3: 97230 | J3: US | K3: (631) 731-0565 | L3: http://www.247.aero/contact/ | M3: PDX | N3: CNSL | Y3: https://maps.google.com/?cid=12255980812482063639 | AB3: 24/7 Flight Support | AD3: ChIJ3bQdlZmjlVQRFy3_LZ39Fao | AE3: 14121 NE Airport Way, Portland, OR 97230, USA | AJ3: 45.561737 | AK3: -122.51725 | AL3: {"html_attributions":[],"result":{"address_components":[{"long_name":"14121","short_name":"14121","types":["street_number"]},{"long_name":"Northeast Airport Way","short_name":"NE Airport Way","types":["route"]},{"long_name":"Argay","short_name":"Argay","types":["neighborhood","political"]},{"long_name":"Portland","short_name":"Portland","types":["locality","political"]},{"long_name":"Multnomah County","short_name":"Multnomah County","types":["administrative_area_level_2","political"]},{"long_name":"Oregon","short_name":"OR","types":["administrative_area_level_1","political"]},{"long_name":"United States","short_name":"US","types":["country","political"]},{"long_name":"97230","short_name":"97230","types":["postal_code"]}],"adr_address":"<span class=\"street-address\">14121 NE Airport Way</span>, <span class=\"locality\">Portland</span>, <span class=\"region\">OR</span> <span class=\"postal-code\">97230</span>, <span class=\"country-name\">USA</span>","formatted_address":"14121 NE Airport Way, Portland, OR 97230, USA","formatted_phone_number":"(631) 731-0565","geometry":{"location":{"lat":45.5617374,"lng":-122.5172475},"viewport":{"northeast":{"lat":45.5629231802915,"lng":-122.5160710697085},"southwest":{"lat":45.5602252197085,"lng":-122.5187690302915}}},"icon":"https://maps.gstatic.com/mapfiles/place_api/icons/v1/png_71/generic_business-71.png","id":null,"international_phone_number":"+1 631-731-0565","name":"24/7 Flight Support","place_id":"ChIJ3bQdlZmjlVQRFy3_LZ39Fao","rating":5.0,"reference":null,"reviews":[{"author_name":"Ammar Eng","author_url":"https://www.google.com/maps/contrib/108465733041230473970/reviews","language":"en","profile_photo_url":"https://lh3.googleusercontent.com/a-/AOh14GjwMOzYWT104gA2VJEy36ksFtBPSs0h_Jg0C_iX=s128-c0x00000000-cc-rp-mo-ba2","rating":5,"relative_time_description":"6 months ago","text":"I love this Road","time":1625093755}],"types":["point_of_interest","establishment"],"url":"https://maps.google.com/?cid=12255980812482063639","utc_offset":-480,"vicinity":"14121 Northeast Airport Way, Portland","website":"http://www.247.aero/contact/"},"status":"OK"} | AM3: <span class="street-address">14121 NE Airport Way</span>, <span class="locality">Portland</span>, <span class="region">OR</span> <span class="postal-code">97230</span>, <span class="country-name">USA</span> | AN3: (631) 731-0565 | AO3: https://maps.gstatic.com/mapfiles/place_api/icons/v1/png_71/generic_business-71.png | AQ3: +1 631-731-0565 | AR3: point_of_interest,establishment | AS3: -480 | AT3: 14121 Northeast Airport Way, Portland | AU3: http://www.247.aero/contact/ | AV3: 5 | AW3: 1
A4: 3 D Aviation Inc | B4: Nassau Flyers | E4: 1300 New Hwy | G4: Farmingdale | H4: NY | I4: 11735-1517 | J4: US | K4: (631) 454-0626 | L4: http://www.flynfi.com/ | M4: FRG | N4: FLT61 | Y4: https://maps.google.com/?cid=9012127429399910560 | AB4: 3 D Aviation Inc | AC4: OPERATIONAL | AD4: ChIJsYGUsBwr6IkRoJjvEyaCEX0 | AE4: 1300 New Hwy, Farmingdale, NY 11735, USA | AJ4: 40.738428 | AK4: -73.413406 | AL4: {"html_attributions":[],"result":{"address_components":[{"long_name":"1300","short_name":"1300","types":["street_number"]},{"long_name":"New Highway","short_name":"New Hwy","types":["route"]},{"long_name":"Farmingdale","short_name":"Farmingdale","types":["locality","political"]},{"long_name":"Babylon","short_name":"Babylon","types":["administrative_area_level_3","political"]},{"long_name":"Suffolk County","short_name":"Suffolk County","types":["administrative_area_level_2","political"]},{"long_name":"New York","short_name":"NY","types":["administrative_area_level_1","political"]},{"long_name":"United States","short_name":"US","types":["country","political"]},{"long_name":"11735","short_name":"11735","types":["postal_code"]},{"long_name":"1517","short_name":"1517","types":["postal_code_suffix"]}],"adr_address":"<span class=\"street-address\">1300 New Hwy</span>, <span class=\"locality\">Farmingdale</span>, <span class=\"region\">NY</span> <span class=\"postal-code\">11735-1517</span>, <span class=\"country-name\">USA</span>","formatted_address":"1300 New Hwy, Farmingdale, NY 11735, USA","formatted_phone_number":"(631) 454-0626","geometry":{"location":{"lat":40.73842820000001,"lng":-73.41340629999999},"viewport":{"northeast":{"lat":40.7397872302915,"lng":-73.41191856970849},"southwest":{"lat":40.73708926970851,"lng":-73.4146165302915}}},"icon":"https://maps.gstatic.com/mapfiles/place_api/icons/v1/png_71/generic_business-71.png","id":null,"international_phone_number":"+1 631-454-0626","name":"3 D Aviation Inc","place_id":"ChIJsYGUsBwr6IkRoJjvEyaCEX0","rating":null,"reference":null,"reviews":null,"types":["point_of_interest","establishment"],"url":"https://maps.google.com/?cid=9012127429399910560","utc_offset":-300,"vicinity":"1300 New Highway, Farmingdale","website":"http://www.flynfi.com/"},"status":"OK"} | AM4: <span class="street-address">1300 New Hwy</span>, <span class="locality">Farmingdale</span>, <span class="region">NY</span> <span class="postal-code">11735-1517</span>, <span class="country-name">USA</span> | AN4: (631) 454-0626 | AO4: https://maps.gstatic.com/mapfiles/place_api/icons/v1/png_71/generic_business-71.png | AQ4: +1 631-454-0626 | AR4: point_of_interest,establishment | AS4: -300 | AT4: 1300 New Highway, Farmingdale | AU4: http://www.flynfi.com/
A5: 3D Aviation Charter & Cargo | B5: Nassau Flyers | E5: 1300 New Hwy | G5: Farmingdale | H5: NY | I5: 11735-1517 | J5: US | K5: (631) 465-0885 | L5: https://www.nassauflyers.com/ | M5: FRG | N5: P135 | O5: CRG | Y5: https://maps.google.com/?cid=11083942137109628795 | AB5: 3D Aviation Charter & Cargo | AC5: OPERATIONAL | AD5: ChIJsYGUsBwr6IkRe0dnAaYS0pk | AE5: 1300 New Hwy, Farmingdale, NY 11735, USA | AJ5: 40.738389 | AK5: -73.413397 | AL5: {"html_attributions":[],"result":{"address_components":[{"long_name":"1300","short_name":"1300","types":["street_number"]},{"long_name":"New Highway","short_name":"New Hwy","types":["route"]},{"long_name":"Farmingdale","short_name":"Farmingdale","types":["locality","political"]},{"long_name":"Babylon","short_name":"Babylon","types":["administrative_area_level_3","political"]},{"long_name":"Suffolk County","short_name":"Suffolk County","types":["administrative_area_level_2","political"]},{"long_name":"New York","short_name":"NY","types":["administrative_area_level_1","political"]},{"long_name":"United States","short_name":"US","types":["country","political"]},{"long_name":"11735","short_name":"11735","types":["postal_code"]},{"long_name":"1517","short_name":"1517","types":["postal_code_suffix"]}],"adr_address":"<span class=\"street-address\">1300 New Hwy</span>, <span class=\"locality\">Farmingdale</span>, <span class=\"region\">NY</span> <span class=\"postal-code\">11735-1517</span>, <span class=\"country-name\">USA</span>","formatted_address":"1300 New Hwy, Farmingdale, NY 11735, USA","formatted_phone_number":"(631) 465-0885","geometry":{"location":{"lat":40.7383893,"lng":-73.41339700000002},"viewport":{"northeast":{"lat":40.73974818029151,"lng":-73.4119114697085},"southwest":{"lat":40.73705021970851,"lng":-73.4146094302915}}},"icon":"https://maps.gstatic.com/mapfiles/place_api/icons/v1/png_71/generic_business-71.png","id":null,"international_phone_number":"+1 631-465-0885","name":"3D Aviation Charter & Cargo","place_id":"ChIJsYGUsBwr6IkRe0dnAaYS0pk","rating":null,"reference":null,"reviews":null,"types":["travel_agency","point_of_interest","establishment"],"url":"https://maps.google.com/?cid=11083942137109628795","utc_offset":-300,"vicinity":"1300 New Highway, Farmingdale","website":null},"status":"OK"} | AM5: <span class="street-address">1300 New Hwy</span>, <span class="locality">Farmingdale</span>, <span class="region">NY</span> <span class="postal-code">11735-1517</span>, <span class="country-name">USA</span> | AN5: (631) 465-0885 | AO5: https://maps.gstatic.com/mapfiles/place_api/icons/v1/png_71/generic_business-71.png | AQ5: +1 631-465-0885 | AR5: travel_agency,point_of_interest,establishment | AS5: -300 | AT5: 1300 New Highway, Farmingdale
A6: 4-J Aviation | G6: Tulsa | H6: OK | I6: 74152-0366 | J6: US | K6: (918) 299-2532 | M6: RVS | Y6: https://maps.google.com/?cid=16083813591999652084 | AB6: 4-J Aviation | AC6: OPERATIONAL | AD6: ChIJVVyuv3vrtocR9CC9CD8vNd8 | AE6: PO Box 52366, Tulsa, OK 74152, USA | AJ6: 36.141869 | AK6: -95.959952 | AL6: {"html_attributions":[],"result":{"address_components":[{"long_name":"PO Box 52366","short_name":"PO Box 52366","types":["post_box"]},{"long_name":"Cherry Street","short_name":"Cherry Street","types":["neighborhood","political"]},{"long_name":"Tulsa","short_name":"Tulsa","types":["locality","political"]},{"long_name":"Tulsa County","short_name":"Tulsa County","types":["administrative_area_level_2","political"]},{"long_name":"Oklahoma","short_name":"OK","types":["administrative_area_level_1","political"]},{"long_name":"United States","short_name":"US","types":["country","political"]},{"long_name":"74152","short_name":"74152","types":["postal_code"]},{"long_name":"0366","short_name":"0366","types":["postal_code_suffix"]}],"adr_address":"<span class=\"post-office-box\">PO Box 52366</span>, <span class=\"locality\">Tulsa</span>, <span class=\"region\">OK</span> <span class=\"postal-code\">74152-0366</span>, <span class=\"country-name\">USA</span>","formatted_address":"PO Box 52366, Tulsa, OK 74152, USA","formatted_phone_number":"(918) 299-2532","geometry":{"location":{"lat":36.1418688,"lng":-95.95995169999999},"viewport":{"northeast":{"lat":36.1432177802915,"lng":-95.95861071970849},"southwest":{"lat":36.1405198197085,"lng":-95.96130868029151}}},"icon":"https://maps.gstatic.com/mapfiles/place_api/icons/v1/png_71/generic_business-71.png","id":null,"international_phone_number":"+1 918-299-2532","name":"4-J Aviation","place_id":"ChIJVVyuv3vrtocR9CC9CD8vNd8","rating":null,"reference":null,"reviews":null,"types":["point_of_interest","establishment"],"url":"https://maps.google.com/?cid=16083813591999652084","utc_offset":-360,"vicinity":"Tulsa","website":null},"status":"OK"} | AM6: <span class="post-office-box">PO Box 52366</span>, <span class="locality">Tulsa</span>, <span class="region">OK</span> <span class="postal-code">74152-0366</span>, <span class="country-name">USA</span> | AN6: (918) 299-2532 | AO6: https://maps.gstatic.com/mapfiles/place_api/icons/v1/png_71/generic_business-71.png | AQ6: +1 918-299-2532 | AR6: point_of_interest,establishment | AS6: -360 | AT6: Tulsa
A7: A & P Aviation Consulting | E7: 2111 Smithtown Ave | G7: Ronkonkoma | H7: NY | I7: 11779-7364 | J7: US | K7: (631) 588-7774 | L7: http://www.apaviationconsulting.com/Home.html | M7: ISP | N7: CNSL | Y7: https://maps.google.com/?cid=4560746926675584844 | AB7: A & P Aviation Consulting | AC7: OPERATIONAL | AD7: ChIJBUpAFbY36IkRTOfzeioHSz8 | AE7: 2111 Smithtown Ave, Ronkonkoma, NY 11779, USA | AJ7: 40.79855 | AK7: -73.110028 | AL7: {"html_attributions":[],"result":{"address_components":[{"long_name":"2111","short_name":"2111","types":["street_number"]},{"long_name":"Smithtown Avenue","short_name":"Smithtown Ave","types":["route"]},{"long_name":"Ronkonkoma","short_name":"Ronkonkoma","types":["locality","political"]},{"long_name":"Islip","short_name":"Islip","types":["administrative_area_level_3","political"]},{"long_name":"Suffolk County","short_name":"Suffolk County","types":["administrative_area_level_2","political"]},{"long_name":"New York","short_name":"NY","types":["administrative_area_level_1","political"]},{"long_name":"United States","short_name":"US","types":["country","political"]},{"long_name":"11779","short_name":"11779","types":["postal_code"]},{"long_name":"7364","short_name":"7364","types":["postal_code_suffix"]}],"adr_address":"<span class=\"street-address\">2111 Smithtown Ave</span>, <span class=\"locality\">Ronkonkoma</span>, <span class=\"region\">NY</span> <span class=\"postal-code\">11779-7364</span>, <span class=\"country-name\">USA</span>","formatted_address":"2111 Smithtown Ave, Ronkonkoma, NY 11779, USA","formatted_phone_number":"(631) 588-7774","geometry":{"location":{"lat":40.7985504,"lng":-73.1100276},"viewport":{"northeast":{"lat":40.7999818802915,"lng":-73.10867806970849},"southwest":{"lat":40.7972839197085,"lng":-73.11137603029151}}},"icon":"https://maps.gstatic.com/mapfiles/place_api/icons/v1/png_71/generic_business-71.png","id":null,"international_phone_number":"+1 631-588-7774","name":"A & P Aviation Consulting","place_id":"ChIJBUpAFbY36IkRTOfzeioHSz8","rating":null,"reference":null,"reviews":null,"types":["point_of_interest","establishment"],"url":"https://maps.google.com/?cid=4560746926675584844","utc_offset":-300,"vicinity":"2111 Smithtown Avenue, Ronkonkoma","website":"http://www.apaviationconsulting.com/Home.html"},"status":"OK"} | AM7: <span class="street-address">2111 Smithtown Ave</span>, <span class="locality">Ronkonkoma</span>, <span class="region">NY</span> <span class="postal-code">11779-7364</span>, <span class="country-name">USA</span> | AN7: (631) 588-7774 | AO7: https://maps.gstatic.com/mapfiles/place_api/icons/v1/png_71/generic_business-71.png | AQ7: +1 631-588-7774 | AR7: point_of_interest,establishment | AS7: -300 | AT7: 2111 Smithtown Avenue, Ronkonkoma | AU7: http://www.apaviationconsulting.com/Home.html
A8: A Different Point of View | E8: 45 Hartley Pl | G8: Santa Barbara | H8: CA | I8: 93117 | J8: US | K8: (805) 698-6784 | L8: http://www.adifferentpointofview.org/ | M8: SBA | N8: NPRO | Y8: https://maps.google.com/?cid=7423200209373708 | AB8: A Different Point of View | AC8: OPERATIONAL | AD8: ChIJ5UX2GYFA6YARDIqTe1xfGgA | AE8: 45 Hartley Pl, Santa Barbara, CA 93117, USA | AJ8: 34.432998 | AK8: -119.83884 | AL8: {"html_attributions":[],"result":{"address_components":[{"long_name":"45","short_name":"45","types":["street_number"]},{"long_name":"Hartley Place","short_name":"Hartley Pl","types":["route"]},{"long_name":"Santa Barbara","short_name":"Santa Barbara","types":["locality","political"]},{"long_name":"Santa Barbara County","short_name":"Santa Barbara County","types":["administrative_area_level_2","political"]},{"long_name":"California","short_name":"CA","types":["administrative_area_level_1","political"]},{"long_name":"United States","short_name":"US","types":["country","political"]},{"long_name":"93117","short_name":"93117","types":["postal_code"]}],"adr_address":"<span class=\"street-address\">45 Hartley Pl</span>, <span class=\"locality\">Santa Barbara</span>, <span class=\"region\">CA</span> <span class=\"postal-code\">93117</span>, <span class=\"country-name\">USA</span>","formatted_address":"45 Hartley Pl, Santa Barbara, CA 93117, USA","formatted_phone_number":"(805) 698-6784","geometry":{"location":{"lat":34.43299769999999,"lng":-119.8388429},"viewport":{"northeast":{"lat":34.4343372802915,"lng":-119.8374574697085},"southwest":{"lat":34.4316393197085,"lng":-119.8401554302915}}},"icon":"https://maps.gstatic.com/mapfiles/place_api/icons/v1/png_71/generic_business-71.png","id":null,"international_phone_number":"+1 805-698-6784","name":"A Different Point of View","place_id":"ChIJ5UX2GYFA6YARDIqTe1xfGgA","rating":5.0,"reference":null,"reviews":[{"author_name":"Paul Andre","author_url":"https://www.google.com/maps/contrib/118104027240777327516/reviews","language":"en","profile_photo_url":"https://lh3.googleusercontent.com/a-/AOh14GhLCr6QDovMUCsnaik9EizYcE8UHRS-3fJ4b9vV=s128-c0x00000000-cc-rp-mo","rating":5,"relative_time_description":"6 years ago","text":"The work ADPOV does for today's youth just takes my breath away. It is transforming the lives of young people, who have not had the advantages of life - like the mind-changing experience of flying - that most of us take for granted. It works. I became a supporter and it's my favorite non-profit. It changes lives.","time":1433370616}],"types":["travel_agency","point_of_interest","establishment"],"url":"https://maps.google.com/?cid=7423200209373708","utc_offset":-480,"vicinity":"45 Hartley Place, Santa Barbara","website":"http://www.adifferentpointofview.org/"},"status":"OK"} | AM8: <span class="street-address">45 Hartley Pl</span>, <span class="locality">Santa Barbara</span>, <span class="region">CA</span> <span class="postal-code">93117</span>, <span class="country-name">USA</span> | AN8: (805) 698-6784 | AO8: https://maps.gstatic.com/mapfiles/place_api/icons/v1/png_71/generic_business-71.png | AQ8: +1 805-698-6784 | AR8: travel_agency,point_of_interest,establishment | AS8: -480 | AT8: 45 Hartley Place, Santa Barbara | AU8: http://www.adifferentpointofview.org/ | AV8: 5 | AW8: 1
A9: A M I R I O N E | G9: Tijuana | H9: B.C. | I9: 22300 | J9: MX | K9: 52790838791 | L9: http://amirione.com/ | M9: TIJ | Y9: https://maps.google.com/?cid=1335117292211012003 | AB9: A M I R I O N E | AC9: OPERATIONAL | AD9: ChIJf2aqLPhI2YARowG4fxpKhxI | AE9: AP 447, Libertad, 22300 Tijuana, B.C., Mexico | AJ9: 32.540637 | AK9: -117.02093 | AL9: {"html_attributions":[],"result":{"address_components":[{"long_name":"Tijuana","short_name":"Tijuana","types":["locality","political"]},{"long_name":"Libertad","short_name":"Libertad","types":["sublocality_level_1","sublocality","political"]},{"long_name":"Baja California","short_name":"B.C.","types":["administrative_area_level_1","political"]},{"long_name":"Mexico","short_name":"MX","types":["country","political"]},{"long_name":"22300","short_name":"22300","types":["postal_code"]}],"adr_address":"AP 447, <span class=\"extended-address\">Libertad</span>, <span class=\"postal-code\">22300</span> <span class=\"locality\">Tijuana</span>, <span class=\"region\">B.C.</span>, <span class=\"country-name\">Mexico</span>","formatted_address":"AP 447, Libertad, 22300 Tijuana, B.C., Mexico","formatted_phone_number":"52790838791","geometry":{"location":{"lat":32.5406369,"lng":-117.0209316},"viewport":{"northeast":{"lat":32.5420511302915,"lng":-117.0195264197085},"southwest":{"lat":32.5393531697085,"lng":-117.0222243802915}}},"icon":"https://maps.gstatic.com/mapfiles/place_api/icons/v1/png_71/school-71.png","id":null,"international_phone_number":"+52 52790838791","name":"A M I R I O N E","place_id":"ChIJf2aqLPhI2YARowG4fxpKhxI","rating":null,"reference":null,"reviews":null,"types":["university","point_of_interest","establishment"],"url":"https://maps.google.com/?cid=1335117292211012003","utc_offset":-480,"vicinity":"AP 447, Tijuana","website":null},"status":"OK"} | AM9: AP 447, <span class="extended-address">Libertad</span>, <span class="postal-code">22300</span> <span class="locality">Tijuana</span>, <span class="region">B.C.</span>, <span class="country-name">Mexico</span> | AN9: 52790838791 | AO9: https://maps.gstatic.com/mapfiles/place_api/icons/v1/png_71/school-71.png | AQ9: +52 52790838791 | AR9: university,point_of_interest,establishment | AS9: -480 | AT9: AP 447, Tijuana
A10: A P D Aviation | E10: 255 El Cielo Rd | F10: # 140 | G10: Palm Springs | H10: CA | I10: 92262-6910 | J10: US | K10: (760) 327-9247 | M10: PSP | Y10: https://maps.google.com/?cid=10564526803655890608 | AB10: A P D Aviation | AC10: OPERATIONAL | AD10: ChIJ_S9DpX8c24ARsJYAmCe9nJI | AE10: 255 El Cielo Rd # 140, Palm Springs, CA 92262, USA | AJ10: 33.825621 | AK10: -116.51163 | AL10: {"html_attributions":[],"result":{"address_components":[{"long_name":"# 140","short_name":"# 140","types":["subpremise"]},{"long_name":"255","short_name":"255","types":["street_number"]},{"long_name":"El Cielo Road","short_name":"El Cielo Rd","types":["route"]},{"long_name":"Palm Springs","short_name":"Palm Springs","types":["locality","political"]},{"long_name":"Riverside County","short_name":"Riverside County","types":["administrative_area_level_2","political"]},{"long_name":"California","short_name":"CA","types":["administrative_area_level_1","political"]},{"long_name":"United States","short_name":"US","types":["country","political"]},{"long_name":"92262","short_name":"92262","types":["postal_code"]},{"long_name":"6910","short_name":"6910","types":["postal_code_suffix"]}],"adr_address":"<span class=\"street-address\">255 El Cielo Rd # 140</span>, <span class=\"locality\">Palm Springs</span>, <span class=\"region\">CA</span> <span class=\"postal-code\">92262-6910</span>, <span class=\"country-name\">USA</span>","formatted_address":"255 El Cielo Rd # 140, Palm Springs, CA 92262, USA","formatted_phone_number":"(760) 327-9247","geometry":{"location":{"lat":33.825621,"lng":-116.511633},"viewport":{"northeast":{"lat":33.82683833029149,"lng":-116.5102864197085},"southwest":{"lat":33.82414036970849,"lng":-116.5129843802915}}},"icon":"https://maps.gstatic.com/mapfiles/place_api/icons/v1/png_71/generic_business-71.png","id":null,"international_phone_number":"+1 760-327-9247","name":"A P D Aviation","place_id":"ChIJ_S9DpX8c24ARsJYAmCe9nJI","rating":null,"reference":null,"reviews":null,"types":["point_of_interest","establishment"],"url":"https://maps.google.com/?cid=10564526803655890608","utc_offset":-480,"vicinity":"255 El Cielo Road # 140, Palm Springs","website":null},"status":"OK"} | AM10: <span class="street-address">255 El Cielo Rd # 140</span>, <span class="locality">Palm Springs</span>, <span class="region">CA</span> <span class="postal-code">92262-6910</span>, <span class="country-name">USA</span> | AN10: (760) 327-9247 | AO10: https://maps.gstatic.com/mapfiles/place_api/icons/v1/png_71/generic_business-71.png | AQ10: +1 760-327-9247 | AR10: point_of_interest,establishment | AS10: -480 | AT10: 255 El Cielo Road # 140, Palm Springs
A11: A-One FS LLC | E11: 37300 Palmdale Rd | G11: Rancho Mirage | H11: CA | I11: 92270-2246 | J11: US | K11: (760) 333-4906 | Y11: https://maps.google.com/?cid=9925962855924586417 | AB11: A-One FS LLC | AD11: ChIJVVVZC5YC24ARsVcboaAawIk | AE11: 37300 Palmdale Rd, Rancho Mirage, CA 92270, USA | AJ11: 33.777322 | AK11: -116.43675 | AL11: {"html_attributions":[],"result":{"address_components":[{"long_name":"37300","short_name":"37300","types":["street_number"]},{"long_name":"Palmdale Road","short_name":"Palmdale Rd","types":["route"]},{"long_name":"Rancho Mirage","short_name":"Rancho Mirage","types":["locality","political"]},{"long_name":"Riverside County","short_name":"Riverside County","types":["administrative_area_level_2","political"]},{"long_name":"California","short_name":"CA","types":["administrative_area_level_1","political"]},{"long_name":"United States","short_name":"US","types":["country","political"]},{"long_name":"92270","short_name":"92270","types":["postal_code"]},{"long_name":"2246","short_name":"2246","types":["postal_code_suffix"]}],"adr_address":"<span class=\"street-address\">37300 Palmdale Rd</span>, <span class=\"locality\">Rancho Mirage</span>, <span class=\"region\">CA</span> <span class=\"postal-code\">92270-2246</span>, <span class=\"country-name\">USA</span>","formatted_address":"37300 Palmdale Rd, Rancho Mirage, CA 92270, USA","formatted_phone_number":"(760) 333-4906","geometry":{"location":{"lat":33.7773218,"lng":-116.4367475},"viewport":{"northeast":{"lat":33.77866468029149,"lng":-116.4354951197085},"southwest":{"lat":33.7759667197085,"lng":-116.4381930802915}}},"icon":"https://maps.gstatic.com/mapfiles/place_api/icons/v1/png_71/generic_business-71.png","id":null,"international_phone_number":"+1 760-333-4906","name":"A-One FS LLC","place_id":"ChIJVVVZC5YC24ARsVcboaAawIk","rating":null,"reference":null,"reviews":null,"types":["point_of_interest","establishment"],"url":"https://maps.google.com/?cid=9925962855924586417","utc_offset":-480,"vicinity":"37300 Palmdale Road, Rancho Mirage","website":null},"status":"OK"} | AM11: <span class="street-address">37300 Palmdale Rd</span>, <span class="locality">Rancho Mirage</span>, <span class="region">CA</span> <span class="postal-code">92270-2246</span>, <span class="country-name">USA</span> | AN11: (760) 333-4906 | AO11: https://maps.gstatic.com/mapfiles/place_api/icons/v1/png_71/generic_business-71.png | AQ11: +1 760-333-4906 | AR11: point_of_interest,establishment | AS11: -480 | AT11: 37300 Palmdale Road, Rancho Mirage
A12: A&P Americas Best AMT Course | G12: Goodyear | H12: AZ | I12: 85338 | J12: US | K12: (602) 284-6994 | L12: http://www.americasbestamtcourses.com/ | M12: GEU | N12: TRNS | Y12: https://maps.google.com/?cid=296734959199369194 | AB12: A&P Americas Best AMT Course | AD12: ChIJWwFBTxw5K4cR6reEi982HgQ | AE12: 1300 South Litchfield Road Building: 150, Suite: A1020, Goodyear, AZ 85338, USA | AJ12: 33.432101 | AK12: -112.36015 | AL12: {"html_attributions":[],"result":{"address_components":[{"long_name":"Goodyear","short_name":"Goodyear","types":["locality","political"]},{"long_name":"Maricopa County","short_name":"Maricopa County","types":["administrative_area_level_2","political"]},{"long_name":"Arizona","short_name":"AZ","types":["administrative_area_level_1","political"]},{"long_name":"United States","short_name":"US","types":["country","political"]},{"long_name":"85338","short_name":"85338","types":["postal_code"]}],"adr_address":"1300 South Litchfield Road Building: 150, Suite: A1020, <span class=\"locality\">Goodyear</span>, <span class=\"region\">AZ</span> <span class=\"postal-code\">85338</span>, <span class=\"country-name\">USA</span>","formatted_address":"1300 South Litchfield Road Building: 150, Suite: A1020, Goodyear, AZ 85338, USA","formatted_phone_number":"(602) 284-6994","geometry":{"location":{"lat":33.4321013,"lng":-112.3601523},"viewport":{"northeast":{"lat":33.4333871302915,"lng":-112.3571457},"southwest":{"lat":33.4306891697085,"lng":-112.3611545}}},"icon":"https://maps.gstatic.com/mapfiles/place_api/icons/v1/png_71/school-71.png","id":null,"international_phone_number":"+1 602-284-6994","name":"A&P Americas Best AMT Course","place_id":"ChIJWwFBTxw5K4cR6reEi982HgQ","rating":4.7,"reference":null,"reviews":[{"author_name":"Mauricio","author_url":"https://www.google.com/maps/contrib/100190515489670838339/reviews","language":"en","profile_photo_url":"https://lh3.googleusercontent.com/a-/AOh14GjcX-uafQbZs23qvd9-Shck961dlgqi2JkDQU-wpQ=s128-c0x00000000-cc-rp-mo-ba4","rating":1,"relative_time_description":"2 months ago","text":"The worst experience that I've had. I payed for a course but never scheduled me, never answered my calls or emails. I'm looking for refund my money but, I think it will be very difficult, these people are opportunists.\nIf you are foreign don't go to this place.","time":1635352330},{"author_name":"Garrett Williams","author_url":"https://www.google.com/maps/contrib/101033541074527730761/reviews","language":"en","profile_photo_url":"https://lh3.googleusercontent.com/a-/AOh14GhbNNo-hbKy68jLJGKoXP1Ll5Ab-fG-Ke_DJv6zmQ=s128-c0x00000000-cc-rp-mo-ba2","rating":5,"relative_time_description":"10 months ago","text":"Antonio is the best instructor out there for this purpose. I just finished with the course and got my A&P. As long as you put in the work, he will help you to help yourself. Highly recommend if you're looking into it.","time":1614892373},{"author_name":"Manatees Moo","author_url":"https://www.google.com/maps/contrib/108463942080003028885/reviews","language":"en","profile_photo_url":"https://lh3.googleusercontent.com/a-/AOh14Ggvy1H3B29B7VMIdzcjbGKxLqB6OcwKZznWwi9myA=s128-c0x00000000-cc-rp-mo-ba6","rating":5,"relative_time_description":"4 months ago","text":"This reviews for the testing center portion of this facility and not its training. Friendly staff, great set up, clean facility, and awesome decor.","time":1629835256},{"author_name":"B","author_url":"https://www.google.com/maps/contrib/100160310465815865276/reviews","language":"en","profile_photo_url":"https://lh3.googleusercontent.com/a/AATXAJxaAJt449HO8jPA-JN-GQW1KLDn4zKHLhzDD7jg=s128-c0x00000000-cc-rp-mo","rating":5,"relative_time_description":"a year ago","text":"I just finished the A & P course there and it was awesome. It was extremely challenging, but Tony and the team at America’s Best AMT get the job done. They were always extremely professional and made the class fun. They were always available to help you out with any challenging areas and didn’t stop until you understood the material and felt comfortable. I highly recommend this course.","time":1582939093},{"author_name":"shane routery","author_url":"https://www.google.com/maps/contrib/115757146187641274885/reviews","language":"en","profile_photo_url":"https://lh3.googleusercontent.com/a/AATXAJycruw_GzZtFl2z0q4AbTpMgKn318k0ChcfrOI=s128-c0x00000000-cc-rp-mo-ba3","rating":5,"relative_time_description":"a year ago","text":"Best place for all military personal! Great staff and awesome instructors!","time":1603211099}],"types":["university","point_of_interest","establishment"],"url":"https://maps.google.com/?cid=296734959199369194","utc_offset":-420,"vicinity":"1300 South Litchfield Road Building: 150, Suite: A1020, Goodyear","website":"http://www.americasbestamtcourses.com/"},"status":"OK"} | AM12: 1300 South Litchfield Road Building: 150, Suite: A1020, <span class="locality">Goodyear</span>, <span class="region">AZ</span> <span class="postal-code">85338</span>, <span class="country-name">USA</span> | AN12: (602) 284-6994 | AO12: https://maps.gstatic.com/mapfiles/place_api/icons/v1/png_71/school-71.png | AQ12: +1 602-284-6994 | AR12: university,point_of_interest,establishment | AS12: -420 | AT12: 1300 South Litchfield Road Building: 150, Suite: A1020, Goodyear | AU12: http://www.americasbestamtcourses.com/ | AV12: 4.7 | AW12: 5
A13: A2M Consulting, LLC | E13: 15655 W Roosevelt St | F13: Ste 225 | G13: Goodyear | H13: AZ | I13: 85338 | J13: US | K13: (702) 351-4204 | L13: http://a2mpc.com/contact/ | M13: GEU | N13: CNSL | Y13: https://maps.google.com/?cid=16890128378300406271 | AB13: A2M Consulting, LLC | AD13: ChIJzRlgo284K4cR_xlXt0XKZeo | AE13: 15655 W Roosevelt St Ste 225, Goodyear, AZ 85338, USA | AJ13: 33.455609 | AK13: -112.39571 | AL13: {"html_attributions":[],"result":{"address_components":[{"long_name":"Ste 225","short_name":"Ste 225","types":["subpremise"]},{"long_name":"15655","short_name":"15655","types":["street_number"]},{"long_name":"West Roosevelt Street","short_name":"W Roosevelt St","types":["route"]},{"long_name":"Canyon Trails","short_name":"Canyon Trails","types":["neighborhood","political"]},{"long_name":"Goodyear","short_name":"Goodyear","types":["locality","political"]},{"long_name":"Maricopa County","short_name":"Maricopa County","types":["administrative_area_level_2","political"]},{"long_name":"Arizona","short_name":"AZ","types":["administrative_area_level_1","political"]},{"long_name":"United States","short_name":"US","types":["country","political"]},{"long_name":"85338","short_name":"85338","types":["postal_code"]}],"adr_address":"<span class=\"street-address\">15655 W Roosevelt St Ste 225</span>, <span class=\"locality\">Goodyear</span>, <span class=\"region\">AZ</span> <span class=\"postal-code\">85338</span>, <span class=\"country-name\">USA</span>","formatted_address":"15655 W Roosevelt St Ste 225, Goodyear, AZ 85338, USA","formatted_phone_number":"(702) 351-4204","geometry":{"location":{"lat":33.4556088,"lng":-112.3957055},"viewport":{"northeast":{"lat":33.4570946302915,"lng":-112.3942859697085},"southwest":{"lat":33.45439666970851,"lng":-112.3969839302915}}},"icon":"https://maps.gstatic.com/mapfiles/place_api/icons/v1/png_71/generic_business-71.png","id":null,"international_phone_number":"+1 702-351-4204","name":"A2M Consulting, LLC","place_id":"ChIJzRlgo284K4cR_xlXt0XKZeo","rating":5.0,"reference":null,"reviews":[{"author_name":"sean caffrey","author_url":"https://www.google.com/maps/contrib/118222312064658504028/reviews","language":"en","profile_photo_url":"https://lh3.googleusercontent.com/a-/AOh14Gg8YUvEDDZAqq8ku3YoeXMJ_Dh-7muWjzGlARKPLQ=s128-c0x00000000-cc-rp-mo","rating":5,"relative_time_description":"a year ago","text":"Had a good time working there for Al.","time":1603225516},{"author_name":"Al Arseo","author_url":"https://www.google.com/maps/contrib/105412599398032545278/reviews","language":null,"profile_photo_url":"https://lh3.googleusercontent.com/a/AATXAJwlB3-OyAPMXJ94HL2-yAh4IG-hOw0s_-6nPWpO=s128-c0x00000000-cc-rp-mo","rating":5,"relative_time_description":"3 years ago","text":"","time":1523931982}],"types":["point_of_interest","establishment"],"url":"https://maps.google.com/?cid=16890128378300406271","utc_offset":-420,"vicinity":"15655 West Roosevelt Street Ste 225, Goodyear","website":"http://a2mpc.com/contact/"},"status":"OK"} | AM13: <span class="street-address">15655 W Roosevelt St Ste 225</span>, <span class="locality">Goodyear</span>, <span class="region">AZ</span> <span class="postal-code">85338</span>, <span class="country-name">USA</span> | AN13: (702) 351-4204 | AO13: https://maps.gstatic.com/mapfiles/place_api/icons/v1/png_71/generic_business-71.png | AQ13: +1 702-351-4204 | AR13: point_of_interest,establishment | AS13: -420 | AT13: 15655 West Roosevelt Street Ste 225, Goodyear | AU13: http://a2mpc.com/contact/ | AV13: 5 | AW13: 2
A14: AA Flight Academy/Museum | E14: 13885 FAA Blvd | G14: Fort Worth | H14: TX | I14: 76155 | J14: US | K14: (848) 480-4217 | M14: DFW | N14: MSM | Y14: https://maps.google.com/?cid=2070084160800623114 | AB14: AA Flight Academy/Museum | AC14: OPERATIONAL | AD14: ChIJIWICQACBToYRCgqvk5Nquhw | AE14: 13885 FAA Blvd, Fort Worth, TX 76155, USA | AJ14: 32.833264 | AK14: -97.063254 | AL14: {"html_attributions":[],"result":{"address_components":[{"long_name":"13885","short_name":"13885","types":["street_number"]},{"long_name":"FAA Boulevard","short_name":"FAA Blvd","types":["route"]},{"long_name":"Fort Worth","short_name":"Fort Worth","types":["locality","political"]},{"long_name":"Tarrant County","short_name":"Tarrant County","types":["administrative_area_level_2","political"]},{"long_name":"Texas","short_name":"TX","types":["administrative_area_level_1","political"]},{"long_name":"United States","short_name":"US","types":["country","political"]},{"long_name":"76155","short_name":"76155","types":["postal_code"]}],"adr_address":"<span class=\"street-address\">13885 FAA Blvd</span>, <span class=\"locality\">Fort Worth</span>, <span class=\"region\">TX</span> <span class=\"postal-code\">76155</span>, <span class=\"country-name\">USA</span>","formatted_address":"13885 FAA Blvd, Fort Worth, TX 76155, USA","formatted_phone_number":"(848) 480-4217","geometry":{"location":{"lat":32.8332643,"lng":-97.06325389999999},"viewport":{"northeast":{"lat":32.8350984302915,"lng":-97.06184246970848},"southwest":{"lat":32.8324004697085,"lng":-97.0645404302915}}},"icon":"https://maps.gstatic.com/mapfiles/place_api/icons/v1/png_71/generic_business-71.png","id":null,"international_phone_number":"+1 848-480-4217","name":"AA Flight Academy/Museum","place_id":"ChIJIWICQACBToYRCgqvk5Nquhw","rating":4.7,"reference":null,"reviews":[{"author_name":"ladi da","author_url":"https://www.google.com/maps/contrib/117515253632858859444/reviews","language":"en","profile_photo_url":"https://lh3.googleusercontent.com/a-/AOh14GjRvKmSpldh9M1qkiGwD2XcLNQNOATQ6L6_zWbyEKE=s128-c0x00000000-cc-rp-mo-ba4","rating":5,"relative_time_description":"a month ago","text":"I loved this visit. Top things to me were the cockpit of the MD80 and the flight simulator. I also enjoyed walking in the old Flagship plane. Overall a wonderful visit.","time":1638659479},{"author_name":"Kyni Hartwell","author_url":"https://www.google.com/maps/contrib/111204301923461641770/reviews","language":"en","profile_photo_url":"https://lh3.googleusercontent.com/a-/AOh14GiHgzNsc1PWqKck5i2LimMEZP_iizizNbj2nZ5Bmw=s128-c0x00000000-cc-rp-mo-ba4","rating":5,"relative_time_description":"3 months ago","text":"Awesome entertainment space for events. The museum portion is amazing to stop and look at all the wonderful aviation history. There are also many interactive areas with great photo ops. I highly recommended this living space and museum. It has many details and is it one of the kind of experience.","time":1632696439},{"author_name":"Veronica Linkletter","author_url":"https://www.google.com/maps/contrib/101107613434055859982/reviews","language":"en","profile_photo_url":"https://lh3.googleusercontent.com/a-/AOh14GhC5SCXwy6i8LazGNGm1csVFd3SBoq-lBua2lanLw=s128-c0x00000000-cc-rp-mo-ba4","rating":4,"relative_time_description":"3 weeks ago","text":"Really neat museum, houses the history of American Airlines. There are flight simulators and a control center area where you can answer questions that the operations center has to handle. There is a kids play area other exhibits.","time":1639854826},{"author_name":"JC Gonzalez","author_url":"https://www.google.com/maps/contrib/113012812803848723682/reviews","language":"en","profile_photo_url":"https://lh3.googleusercontent.com/a/AATXAJzL6cxZjwRCAnfDoRFiUFS3ojF5pjUlh4x5D6sq=s128-c0x00000000-cc-rp-mo-ba3","rating":5,"relative_time_description":"3 months ago","text":"A nice place to visit, minutes from DFW, if you have a few hours between flights.","time":1631564298},{"author_name":"Kelly O'Donnell","author_url":"https://www.google.com/maps/contrib/114140844515925276073/reviews","language":"en","profile_photo_url":"https://lh3.googleusercontent.com/a-/AOh14GhWp2ecf1Y4YWe65FfUVt75F7bUlSMcxSG5ykYQ=s128-c0x00000000-cc-rp-mo","rating":5,"relative_time_description":"4 months ago","text":"Wonderful museum with a great staff. My boys loved the MD 80 cockpit!!","time":1628964326}],"types":["point_of_interest","establishment"],"url":"https://maps.google.com/?cid=2070084160800623114","utc_offset":-360,"vicinity":"13885 FAA Boulevard, Fort Worth","website":null},"status":"OK"} | AM14: <span class="street-address">13885 FAA Blvd</span>, <span class="locality">Fort Worth</span>, <span class="region">TX</span> <span class="postal-code">76155</span>, <span class="country-name">USA</span> | AN14: (848) 480-4217 | AO14: https://maps.gstatic.com/mapfiles/place_api/icons/v1/png_71/generic_business-71.png | AQ14: +1 848-480-4217 | AR14: point_of_interest,establishment | AS14: -360 | AT14: 13885 FAA Boulevard, Fort Worth | AV14: 4.7 | AW14: 5
A15: Aaco Avionics | E15: 9626 Rainier Ave S | G15: Seattle | H15: WA | I15: 98118-5935 | J15: US | K15: (206) 722-1571 | M15: SEA | N15: AVIONICS | Y15: https://maps.google.com/?cid=8427022462202789736 | AB15: Aaco Avionics | AC15: OPERATIONAL | AD15: ChIJCUd-R3dCkFQRaL_V9UfM8nQ | AE15: 9626 Rainier Ave S, Seattle, WA 98118, USA | AJ15: 47.518832 | AK15: -122.25631 | AL15: {"html_attributions":[],"result":{"address_components":[{"long_name":"9626","short_name":"9626","types":["street_number"]},{"long_name":"Rainier Avenue South","short_name":"Rainier Ave S","types":["route"]},{"long_name":"Seattle","short_name":"Seattle","types":["locality","political"]},{"long_name":"King County","short_name":"King County","types":["administrative_area_level_2","political"]},{"long_name":"Washington","short_name":"WA","types":["administrative_area_level_1","political"]},{"long_name":"United States","short_name":"US","types":["country","political"]},{"long_name":"98118","short_name":"98118","types":["postal_code"]},{"long_name":"5935","short_name":"5935","types":["postal_code_suffix"]}],"adr_address":"<span class=\"street-address\">9626 Rainier Ave S</span>, <span class=\"locality\">Seattle</span>, <span class=\"region\">WA</span> <span class=\"postal-code\">98118-5935</span>, <span class=\"country-name\">USA</span>","formatted_address":"9626 Rainier Ave S, Seattle, WA 98118, USA","formatted_phone_number":"(206) 722-1571","geometry":{"location":{"lat":47.518832,"lng":-122.2563109},"viewport":{"northeast":{"lat":47.52010913029149,"lng":-122.2550731197085},"southwest":{"lat":47.5174111697085,"lng":-122.2577710802915}}},"icon":"https://maps.gstatic.com/mapfiles/place_api/icons/v1/png_71/generic_business-71.png","id":null,"international_phone_number":"+1 206-722-1571","name":"Aaco Avionics","place_id":"ChIJCUd-R3dCkFQRaL_V9UfM8nQ","rating":null,"reference":null,"reviews":null,"types":["point_of_interest","establishment"],"url":"https://maps.google.com/?cid=8427022462202789736","utc_offset":-480,"vicinity":"9626 Rainier Avenue South, Seattle","website":null},"status":"OK"} | AM15: <span class="street-address">9626 Rainier Ave S</span>, <span class="locality">Seattle</span>, <span class="region">WA</span> <span class="postal-code">98118-5935</span>, <span class="country-name">USA</span> | AN15: (206) 722-1571 | AO15: https://maps.gstatic.com/mapfiles/place_api/icons/v1/png_71/generic_business-71.png | AQ15: +1 206-722-1571 | AR15: point_of_interest,establishment | AS15: -480 | AT15: 9626 Rainier Avenue South, Seattle
A16: ABM | Aviation | E16: 2300 Valley View Ln | F16: #150 | G16: Irving | H16: TX | I16: 75062 | J16: US | K16: (469) 647-5914 | L16: https://www.abm.com/careers/ | M16: DFW | N16: RECT | Y16: https://maps.google.com/?cid=12849398551782558568 | AB16: ABM Industries | AD16: ChIJsTpLHIKBToYRaAtrYOc7UrI | AE16: 2300 Valley View Ln #150, Irving, TX 75062, USA | AJ16: 32.839836 | AK16: -97.020832 | AL16: {"html_attributions":[],"result":{"address_components":[{"long_name":"#150","short_name":"#150","types":["subpremise"]},{"long_name":"2300","short_name":"2300","types":["street_number"]},{"long_name":"Valley View Lane","short_name":"Valley View Ln","types":["route"]},{"long_name":"Irving","short_name":"Irving","types":["locality","political"]},{"long_name":"Dallas County","short_name":"Dallas County","types":["administrative_area_level_2","political"]},{"long_name":"Texas","short_name":"TX","types":["administrative_area_level_1","political"]},{"long_name":"United States","short_name":"US","types":["country","political"]},{"long_name":"75062","short_name":"75062","types":["postal_code"]}],"adr_address":"<span class=\"street-address\">2300 Valley View Ln #150</span>, <span class=\"locality\">Irving</span>, <span class=\"region\">TX</span> <span class=\"postal-code\">75062</span>, <span class=\"country-name\">USA</span>","formatted_address":"2300 Valley View Ln #150, Irving, TX 75062, USA","formatted_phone_number":"(469) 647-5914","geometry":{"location":{"lat":32.83983589999999,"lng":-97.02083239999999},"viewport":{"northeast":{"lat":32.8410726802915,"lng":-97.01946001970849},"southwest":{"lat":32.8383747197085,"lng":-97.02215798029151}}},"icon":"https://maps.gstatic.com/mapfiles/place_api/icons/v1/png_71/school-71.png","id":null,"international_phone_number":"+1 469-647-5914","name":"ABM Industries","place_id":"ChIJsTpLHIKBToYRaAtrYOc7UrI","rating":2.8,"reference":null,"reviews":[{"author_name":"DT","author_url":"https://www.google.com/maps/contrib/111706885382491558854/reviews","language":"en","profile_photo_url":"https://lh3.googleusercontent.com/a/AATXAJyxy1kmBCdx90bw-ya8Etk47MtMjA3WrKQu4_u8=s128-c0x00000000-cc-rp-mo","rating":1,"relative_time_description":"a month ago","text":"I have an interview here tomorrow but after these reviews I'm scared to go😬","time":1639610040},{"author_name":"Richard Anderson","author_url":"https://www.google.com/maps/contrib/102099525037672421928/reviews","language":"en","profile_photo_url":"https://lh3.googleusercontent.com/a-/AOh14GhmYfukOx_SzTJuGNGttYCyP7xMW7fHoayMlHFerg=s128-c0x00000000-cc-rp-mo","rating":3,"relative_time_description":"a month ago","text":"It's non-stop driving on bus routes.","time":1639599632},{"author_name":"Lamont Taylor","author_url":"https://www.google.com/maps/contrib/114180552043246050201/reviews","language":"en","profile_photo_url":"https://lh3.googleusercontent.com/a/AATXAJzU3wMQU39A5-3-QPqBUS5smU4y_ccWU4rJ69wp=s128-c0x00000000-cc-rp-mo","rating":5,"relative_time_description":"7 months ago","text":"Very friendly people and I will enjoy working there","time":1623371764},{"author_name":"Amanda C","author_url":"https://www.google.com/maps/contrib/106464098680890407341/reviews","language":"en","profile_photo_url":"https://lh3.googleusercontent.com/a-/AOh14GgAq2JqVm6WiDoWAvdySKA-h7EImtyBMy9kUVN7=s128-c0x00000000-cc-rp-mo","rating":1,"relative_time_description":"5 months ago","text":"Down right rude people work for this company.","time":1627755964},{"author_name":"Alexis Harmon","author_url":"https://www.google.com/maps/contrib/101904813653223178881/reviews","language":"en","profile_photo_url":"https://lh3.googleusercontent.com/a/AATXAJw9h81K3gXOjXv8bkVgFNXjrZQ9kt3AMJkAUgvv=s128-c0x00000000-cc-rp-mo","rating":1,"relative_time_description":"a year ago","text":"Not very professional and very disorganized. You will get into a verbal altercation. Looking for another job at this moment . Will not stay to be treated terribly, especially not at this pay rate .","time":1579901797}],"types":["point_of_interest","establishment"],"url":"https://maps.google.com/?cid=12849398551782558568","utc_offset":-360,"vicinity":"2300 Valley View Lane #150, Irving","website":"https://www.abm.com/careers/"},"status":"OK"} | AM16: <span class="street-address">2300 Valley View Ln #150</span>, <span class="locality">Irving</span>, <span class="region">TX</span> <span class="postal-code">75062</span>, <span class="country-name">USA</span> | AN16: (469) 647-5914 | AO16: https://maps.gstatic.com/mapfiles/place_api/icons/v1/png_71/school-71.png | AQ16: +1 469-647-5914 | AR16: point_of_interest,establishment | AS16: -360 | AT16: 2300 Valley View Lane #150, Irving | AU16: https://www.abm.com/careers/ | AV16: 2.8 | AW16: 5
A17: Above All Aviation | E17: 1523 Cook Pl | G17: Santa Barbara | H17: CA | I17: 93117 | J17: US | K17: (805) 683-7575 | L17: http://www.aboveallsba.com/ | M17: SBA | N17: FLT61 | O17: FLT141 | Y17: https://maps.google.com/?cid=5290151183609906946 | AB17: Above All Aviation | AC17: OPERATIONAL | AD17: ChIJm1lhdYI_6YARAkcuG3lkakk | AE17: 1523 Cook Pl, Santa Barbara, CA 93117, USA | AJ17: 34.429697 | AK17: -119.84488 | AL17: {"html_attributions":[],"result":{"address_components":[{"long_name":"1523","short_name":"1523","types":["street_number"]},{"long_name":"Cook Place","short_name":"Cook Pl","types":["route"]},{"long_name":"Santa Barbara","short_name":"Santa Barbara","types":["locality","political"]},{"long_name":"Santa Barbara County","short_name":"Santa Barbara County","types":["administrative_area_level_2","political"]},{"long_name":"California","short_name":"CA","types":["administrative_area_level_1","political"]},{"long_name":"United States","short_name":"US","types":["country","political"]},{"long_name":"93117","short_name":"93117","types":["postal_code"]}],"adr_address":"<span class=\"street-address\">1523 Cook Pl</span>, <span class=\"locality\">Santa Barbara</span>, <span class=\"region\">CA</span> <span class=\"postal-code\">93117</span>, <span class=\"country-name\">USA</span>","formatted_address":"1523 Cook Pl, Santa Barbara, CA 93117, USA","formatted_phone_number":"(805) 683-7575","geometry":{"location":{"lat":34.42969739999999,"lng":-119.8448822},"viewport":{"northeast":{"lat":34.4310578302915,"lng":-119.8439841697085},"southwest":{"lat":34.4283598697085,"lng":-119.8466821302915}}},"icon":"https://maps.gstatic.com/mapfiles/place_api/icons/v1/png_71/school-71.png","id":null,"international_phone_number":"+1 805-683-7575","name":"Above All Aviation","place_id":"ChIJm1lhdYI_6YARAkcuG3lkakk","rating":4.7,"reference":null,"reviews":[{"author_name":"Igor D'Angelo","author_url":"https://www.google.com/maps/contrib/112571911736698558034/reviews","language":"en","profile_photo_url":"https://lh3.googleusercontent.com/a-/AOh14GhO_oh2HZUaPOF49WLXP8ca2f2PKa0aCgxz7kuNBA=s128-c0x00000000-cc-rp-mo-ba2","rating":5,"relative_time_description":"7 months ago","text":"I can't say enough positive things about this flight school. Everyone is simply fantastic, professional and a pleasure to work with. A special 'thank you' to Juliet for being a truly outstanding instructor.","time":1621886254},{"author_name":"Charles Ray","author_url":"https://www.google.com/maps/contrib/112547477137212425213/reviews","language":"en","profile_photo_url":"https://lh3.googleusercontent.com/a-/AOh14Gj3ErdARXdbtbnSr-g6gOovgYDzwQcLasi4TFfkhw=s128-c0x00000000-cc-rp-mo-ba3","rating":5,"relative_time_description":"a year ago","text":"This is where I'm getting my BFR (bi-annual flight review) and they are very thorough and attentive, but they do try to drag out the instruction so you have to pay more, and if you miss a lesson and cancel in advance, they still charge you.","time":1607637775},{"author_name":"Jay Ward","author_url":"https://www.google.com/maps/contrib/116031611364296692863/reviews","language":"en","profile_photo_url":"https://lh3.googleusercontent.com/a-/AOh14GiygULg1KGwKpYwb6tRe87rF_OkpyxUNMWu-3odpA=s128-c0x00000000-cc-rp-mo","rating":5,"relative_time_description":"2 years ago","text":"Above all aviation is amazing! Great staff and great testing center! The owner is very helpful! I can’t say enough good things about the place!","time":1575559986},{"author_name":"Mark S","author_url":"https://www.google.com/maps/contrib/113758101848201964592/reviews","language":"en","profile_photo_url":"https://lh3.googleusercontent.com/a/AATXAJzEDXMGDFVlLIOIO4zEmD6H8GMrPyypaPaTtNtx=s128-c0x00000000-cc-rp-mo","rating":5,"relative_time_description":"a year ago","text":"I wanted to rent an aircraft to take my girlfriend up flying and propose afterwards. Everyone at Above All Aviation were very professional and quick to respond to any questions I had. The aircraft were well maintained and they were very accommodating. I would highly recommend to anyone looking to learn how to fly or rent an aircraft for a few hours to go through Above All Aviation. I will definitely fly through them again.","time":1603729985},{"author_name":"Mitch McCarley","author_url":"https://www.google.com/maps/contrib/106382280856245329971/reviews","language":"en","profile_photo_url":"https://lh3.googleusercontent.com/a-/AOh14Ggye2eDWlO7VFECATvT7WHpa2Nvuf6GSYeezag=s128-c0x00000000-cc-rp-mo-ba2","rating":5,"relative_time_description":"8 months ago","text":"Great scenic flight tour of Santa Barbara and Santa Ynez. Thanks Steve!","time":1618880149}],"types":["university","point_of_interest","establishment"],"url":"https://maps.google.com/?cid=5290151183609906946","utc_offset":-480,"vicinity":"1523 Cook Place, Santa Barbara","website":"http://www.aboveallsba.com/"},"status":"OK"} | AM17: <span class="street-address">1523 Cook Pl</span>, <span class="locality">Santa Barbara</span>, <span class="region">CA</span> <span class="postal-code">93117</span>, <span class="country-name">USA</span> | AN17: (805) 683-7575 | AO17: https://maps.gstatic.com/mapfiles/place_api/icons/v1/png_71/school-71.png | AQ17: +1 805-683-7575 | AR17: university,point_of_interest,establishment | AS17: -480 | AT17: 1523 Cook Place, Santa Barbara | AU17: http://www.aboveallsba.com/ | AV17: 4.7 | AW17: 5
